Workbook

Sheet Cover
B1: Project Lodestone — Centerra Gold / Ero Copper
B2: Hypothetical buy-side merger analysis. Public information only. Not investment advice. Not affiliated with any bank. See DISCLAIMER.md.
B4: Tab | C4: Contents
B5: Inputs | C5: Price deck, FX, price-case selectors, discount rates
B6: Market | C6: yfinance snapshot: prices, shares, balance sheet, TTM metrics
B7: MtMilligan … Xavantina | C7: One life-of-mine NAV model per asset
B8: Corporate_NAV | C8: NAV roll-up, NAV per share, P/NAV and 2027–28E financial summary
B9: Comps | C9: Peer trading multiples (written by scripts/build_comps.py)
B10: Precedents | C10: Copper and gold M&A precedents: premiums, P/NAV, value per reserve ounce
B11: Synergies | C11: US$155M run-rate synergy case, phase-in and NPV
B12: Merger | C12: Offer, exchange ratio, funding, ownership, accretion/dilution to EPS, CFPS and NAVPS
B13: Contribution | C13: Contribution analysis versus pro forma ownership
B14: Scenarios | C14: Outputs under each price case (filled by scripts/run_scenarios.py)
B15: Sensitivity | C15: Premium vs copper price; synergies vs consideration mix
... B26: Market snapshot | C26: 20261025T0009Z

Sheet Inputs
B1: Inputs
B2: Price deck, FX, price-case selectors and discount rates. Edit blue cells (or the CSVs under data/ and rebuild).
B4: Spot market (yfinance snapshot 20261025T0009Z)
B5: Copper spot (COMEX HG) | C5: 6.476 | D5: US$/lb | E5: Source: MKT-YF (data/market/latest_macro.csv)
B6: Gold spot (COMEX GC) | C6: 4007.8999 | D6: US$/oz | E6: Source: MKT-YF (data/market/latest_macro.csv)
B7: CAD/USD spot | C7: 0.7141 | D7: US$ per C$ | E7: Source: MKT-YF (data/market/latest_macro.csv)
B9: Price case selectors (1 = analyst deck, 2 = spot held flat, 3 = custom flat)
B10: Copper price case | C10: 1
B11: Gold price case | C11: 1
B12: Custom copper price (US$/lb) | C12: 4.5
B13: Custom gold price (US$/oz) | C13: 3000
B15: Price deck | E15: Source | F15: 2027 | G15: 2028 | H15: 2029 | I15: 2030 | J15: 2031 | K15: 2032 | L15: 2033 | M15: 2034 | N15: 2035 | O15: 2036 | P15: 2037 | Q15: 2038 | R15: 2039 | S15: 2040 | T15: 2041 | U15: 2042 | V15: 2043 | W15: 2044 | X15: 2045 | Y15: 2046 | Z15: 2047 | AA15: 2048 | AB15: 2049 | AC15: 2050
B16: Copper deck (US$/lb) | E16: data/price_deck.csv; last deck year held flat | F16: 6 | G16: 5.5 | H16: 5 | I16: 5 | J16: 5 | K16: 5 | L16: 5 | M16: 5 | N16: 5 | O16: 5 | P16: 5 | Q16: 5 | R16: 5 | S16: 5 | T16: 5 | U16: 5 | V16: 5 | W16: 5 | X16: 5 | Y16: 5 | Z16: 5 | AA16: 5 | AB16: 5 | AC16: 5
B17: Gold deck (US$/oz) | E17: data/price_deck.csv; last deck year held flat | F17: 3900 | G17: 3600 | H17: 3300 | I17: 3300 | J17: 3300 | K17: 3300 | L17: 3300 | M17: 3300 | N17: 3300 | O17: 3300 | P17: 3300 | Q17: 3300 | R17: 3300 | S17: 3300 | T17: 3300 | U17: 3300 | V17: 3300 | W17: 3300 | X17: 3300 | Y17: 3300 | Z17: 3300 | AA17: 3300 | AB17: 3300 | AC17: 3300
B18: Copper price used in model (US$/lb) | E18: CHOOSE(case, deck, spot, custom) | F18: =CHOOSE($C$10,F16,$C$5,$C$12) -> 6 | G18: =CHOOSE($C$10,G16,$C$5,$C$12) -> 5.5 | H18: =CHOOSE($C$10,H16,$C$5,$C$12) -> 5 | I18: =CHOOSE($C$10,I16,$C$5,$C$12) -> 5 | J18: =CHOOSE($C$10,J16,$C$5,$C$12) -> 5 | K18: =CHOOSE($C$10,K16,$C$5,$C$12) -> 5 | L18: =CHOOSE($C$10,L16,$C$5,$C$12) -> 5 | M18: =CHOOSE($C$10,M16,$C$5,$C$12) -> 5 | ... AC18: =CHOOSE($C$10,AC16,$C$5,$C$12) -> 5
B19: Gold price used in model (US$/oz) | E19: CHOOSE(case, deck, spot, custom) | F19: =CHOOSE($C$11,F17,$C$6,$C$13) -> 3900 | G19: =CHOOSE($C$11,G17,$C$6,$C$13) -> 3600 | H19: =CHOOSE($C$11,H17,$C$6,$C$13) -> 3300 | I19: =CHOOSE($C$11,I17,$C$6,$C$13) -> 3300 | J19: =CHOOSE($C$11,J17,$C$6,$C$13) -> 3300 | K19: =CHOOSE($C$11,K17,$C$6,$C$13) -> 3300 | L19: =CHOOSE($C$11,L17,$C$6,$C$13) -> 3300 | M19: =CHOOSE($C$11,M17,$C$6,$C$13) -> 3300 | ... AC19: =CHOOSE($C$11,AC17,$C$6,$C$13) -> 3300
B21: Discount rate (real) | C21: Rate | E21: Rationale
B22: Mount Milligan | C22: 0.065 | E22: Blended: roughly 50/50 gold/copper revenue after the Royal Gold stream, midway between 5% gold and 8% copper conventions
B23: Öksüt | C23: 0.05 | E23: Gold heap leach; sell-side gold convention (5% real)
B24: Goldfield | C24: 0.05 | E24: Gold heap leach development in Nevada; 5% real gold convention
B25: Caraíba | C25: 0.08 | E25: Copper concentrator; sell-side copper convention (8% real)
B26: Tucumã | C26: 0.08 | E26: Copper concentrator; sell-side copper convention (8% real)
B27: Xavantina | C27: 0.05 | E27: Underground gold; 5% real gold convention
B29: Corporate
B30: G&A capitalisation (years) | C30: 10
B31: G&A discount rate | C31: 0.05

Sheet Market
B1: Market data
B2: yfinance snapshot 20261025T0009Z (scripts/fetch_market_data.py). Balance sheet and TTM figures converted to US$M.
B4: Ticker | C4: Company | D4: Price (C$) | E4: Shares (M) | F4: Mkt cap (US$M) | G4: Cash (US$M) | H4: Debt (US$M) | I4: EV (US$M) | J4: EBITDA TTM (US$M) | K4: CFO TTM (US$M) | L4: EPS TTM (US$) | M4: 52w low (C$) | N4: 52w high (C$) | O4: Target low (C$) | P4: Target mean (C$) | Q4: Target high (C$)
B5: CG.TO | C5: Centerra Gold | D5: 28.32 | E5: 198.59506 | F5: 4016.1465 | G5: 453.10301 | H5: 45.762 | I5: 3608.8055 | J5: 859.96064 | K5: 450.99002 | L5: 4.35 | M5: 14.65 | N5: 33.94 | O5: 22.522635 | P5: 33.624023 | Q5: 44.73018
B6: ERO.TO | C6: Ero Copper | D6: 42.03 | E6: 104.30263 | F6: 3130.4194 | G6: 101.742 | H6: 573.35501 | I6: 3602.0324 | J6: 517.02598 | K6: 470.05901 | L6: 4.08 | M6: 27.22 | N6: 56.62 | O6: 47 | P6: 56.83312 | Q6: 68
B7: CS.TO | C7: Capstone Copper | D7: 11.19 | E7: 763.94934 | F7: 6104.3934 | G7: 371.16899 | H7: 1567.668 | I7: 7300.8924 | J7: 985.72403 | K7: 827.24698 | L7: 0.84 | M7: 9.3 | N7: 18.04 | O7: 15 | P7: 18.009 | Q7: 22
B8: TXG.TO | C8: Torex Gold | D8: 67.14 | E8: 92.594592 | F8: 4439.3034 | G8: 169.4 | H8: 99.4 | I8: 4369.3034 | J8: 1063.4 | K8: 808.49997 | L8: 9 | M8: 51.4 | N8: 85 | O8: 85 | P8: 95.3 | Q8: 105
B9: OGC.TO | C9: OceanaGold | D9: 34.67 | E9: 222.44752 | F9: 5507.1802 | G9: 654.8 | H9: 50.1 | I9: 4902.4802 | J9: 1436.5 | K9: 1280.8 | L9: 5.21 | M9: 29.52 | N9: 59.2 | O9: 44.856213 | P9: 56.97794 | Q9: 72.56313
B10: SSRM.TO | C10: SSR Mining | D10: 39.75 | E10: 207.49107 | F10: 5889.5812 | G10: 1833.964 | H10: 2.3 | I10: 4057.9172 | J10: 863.728 | K10: 596.752 | L10: 4.12 | M10: 25.83 | N10: 54.5 | O10: 51.834408 | P10: 58.111282 | Q10: 67.59311
B11: HBM.TO | C11: Hudbay Minerals | D11: 30.76 | E11: 444.14476 | F11: 9755.7069 | G11: 890.89997 | H11: 1044.5 | I11: 9909.3069 | J11: 1146.5999 | K11: 830.89997 | L11: 2.36 | M11: 20.26 | N11: 44.48 | O11: 39.33584 | P11: 45.203106 | Q11: 51.834408
B12: LUN.TO | C12: Lundin Mining | D12: 29.5 | E12: 851.35956 | F12: 17934.237 | G12: 265.8 | H12: 388.6 | I12: 18057.037 | J12: 2177.9999 | K12: 1781.9 | L12: 2.16 | M12: 21.2 | N12: 45.74 | O12: 32.529892 | P12: 42.956738 | Q12: 53.215202
B13: ELD.TO | C13: Eldorado Gold | D13: 44.32 | E13: 260.81033 | F13: 8254.1511 | G13: 554.56198 | H13: 1763.135 | I13: 9462.7241 | J13: 1151.0159 | K13: 744.20301 | L13: 3.97 | M13: 34.25 | N13: 69.46 | O13: 44.856213 | P13: 65.56697 | Q13: 77.53315
B14: DPM.TO | C14: DPM Metals | D14: 56.02 | E14: 219.36865 | F14: 8775.372 | G14: 761.20902 | H14: 8.413 | I14: 8022.576 | J14: 859.67898 | K14: 768.27501 | L14: 4.27 | M14: 29.12 | N14: 72.54 | O14: 59.8699 | P14: 69.76349 | Q14: 81.50888
B15: IMG.TO | C15: IAMGOLD | D15: 22.72 | E15: 571 | F15: 9263.8669 | G15: 502.4 | H15: 539.8 | I15: 9301.2669 | J15: 2051.0001 | K15: 1997.5 | L15: 2.74 | M15: 15.3 | N15: 34.09 | O15: 31.185507 | P15: 33.98911 | Q15: 35.92026
B16: EQX.TO | C16: Equinox Gold | D16: 14.13 | E16: 1167.4598 | F16: 11779.639 | G16: 481.57798 | H16: 839.05498 | I16: 12137.116 | J16: 1689.365 | K16: 1071.262 | L16: 0.66 | M16: 11.91 | N16: 25.87 | O16: 19.305916 | P16: 24.473698 | Q16: 30.691168
B18: Source: MKT-YF. Values are hardcoded inputs refreshed by the pipeline.

Sheet MtMilligan
B1: Mount Milligan — asset NAV (CG, Canada (BC))
B2: Reserve-constrained life-of-mine model. Blue = input (data/assets.csv), green = link, black = formula. US$M real unless noted.
B4: Input | C4: Value | D4: Unit | F4: Source / status
B5: Ownership | C5: 1 | D5: % | F5: Source IDs: CG-MRMR-2025;CG-MTM-PFS-2025;CG-Q2-2026;CG-RGLD-STREAM (see Sources tab)
B6: P&P reserve (at effective date) | C6: 470.332 | D6: Mt | F6: [verified] reserve_mt|au_gpt: Year-end 2025 P&P 470.3 Mt @ 0.28 g/t Au (CG-MRMR-2025)
B7: Depletion to 1 Jan 2027 | C7: 21.5 | D7: Mt | F7: [estimate] cu_grade_pct: Copper grade not captured from the MRMR table; 0.16% Cu calibrated to 50–60 Mlb/yr 2026 guidance
B8: Copper grade | C8: 0.0016 | D8: % Cu | F8: [verified] expansion_mtpa|expansion_year|growth_capex_usd_m: PFS: ~10% throughput increase in 2029 and US$186M growth capital
B9: Gold grade | C9: 0.28 | D9: g/t Au | F9: [calibrated] recoveries|opex_usd_t|sustaining_usd_m: Set so 2027 AISC lands in the US$1.2–1.3k/oz guidance range
B10: Copper recovery | C10: 0.8 | D10: % | F10: [verified] stream_*: Royal Gold stream: 35% of gold at US$435/oz; 18.75% of copper at 15% of spot
B11: Gold recovery | C11: 0.64 | D11: % | F11: [estimate] depleted_mt: 2026 ore processed (~59 ktpd)
B12: Copper payable | C12: 0.965 | D12: %
B13: Gold payable | C13: 0.97 | D13: %
B14: Throughput | C14: 21.5 | D14: Mtpa
B15: Throughput after expansion | C15: 23.65 | D15: Mtpa
B16: Expansion year | C16: 2029 | D16: year
B17: First production year | C17: 2027 | D17: year
B18: Site operating cost | C18: 13.5 | D18: US$/t milled
B19: TC/RC and freight | C19: 0.45 | D19: US$/lb Cu
B20: Sustaining capex | C20: 90 | D20: US$M/yr
B21: Growth capex (total) | C21: 186 | D21: US$M
B22: Growth capex start | C22: 2027 | D22: year
B23: Growth capex years | C23: 3 | D23: years
... B30: Stream copper price received | C30: 0.15 | D30: % of spot
B31: Discount rate (real) | C31: =Inputs!$C$22 -> 0.065 | D31: Inputs tab
B34: US$M unless noted | C34: Unit | D34: LOM / NPV | F34: 2027 | G34: 2028 | H34: 2029 | I34: 2030 | J34: 2031 | K34: 2032 | L34: 2033 | M34: 2034 | N34: 2035 | O34: 2036 | P34: 2037 | Q34: 2038 | R34: 2039 | S34: 2040 | T34: 2041 | U34: 2042 | V34: 2043 | W34: 2044 | X34: 2045 | Y34: 2046 | Z34: 2047 | AA34: 2048 | AB34: 2049 | AC34: 2050
B35: Period | F35: =F$34-2027+1 -> 1 | G35: =G$34-2027+1 -> 2 | H35: =H$34-2027+1 -> 3 | I35: =I$34-2027+1 -> 4 | J35: =J$34-2027+1 -> 5 | K35: =K$34-2027+1 -> 6 | L35: =L$34-2027+1 -> 7 | M35: =M$34-2027+1 -> 8 | ... AC35: =AC$34-2027+1 -> 24
B36: Copper price | C36: US$/lb | F36: =Inputs!F$18 -> 6 | G36: =Inputs!G$18 -> 5.5 | H36: =Inputs!H$18 -> 5 | I36: =Inputs!I$18 -> 5 | J36: =Inputs!J$18 -> 5 | K36: =Inputs!K$18 -> 5 | L36: =Inputs!L$18 -> 5 | M36: =Inputs!M$18 -> 5 | ... AC36: =Inputs!AC$18 -> 5
B37: Gold price | C37: US$/oz | F37: =Inputs!F$19 -> 3900 | G37: =Inputs!G$19 -> 3600 | H37: =Inputs!H$19 -> 3300 | I37: =Inputs!I$19 -> 3300 | J37: =Inputs!J$19 -> 3300 | K37: =Inputs!K$19 -> 3300 | L37: =Inputs!L$19 -> 3300 | M37: =Inputs!M$19 -> 3300 | ... AC37: =Inputs!AC$19 -> 3300
B38: Mill capacity | C38: Mt | F38: =IF(F$34<$C$17,0,IF(F$34>=$C$16,$C$15,$C$14)) -> 21.5 | G38: =IF(G$34<$C$17,0,IF(G$34>=$C$16,$C$15,$C$14)) -> 21.5 | H38: =IF(H$34<$C$17,0,IF(H$34>=$C$16,$C$15,$C$14)) -> 23.65 | I38: =IF(I$34<$C$17,0,IF(I$34>=$C$16,$C$15,$C$14)) -> 23.65 | J38: =IF(J$34<$C$17,0,IF(J$34>=$C$16,$C$15,$C$14)) -> 23.65 | K38: =IF(K$34<$C$17,0,IF(K$34>=$C$16,$C$15,$C$14)) -> 23.65 | L38: =IF(L$34<$C$17,0,IF(L$34>=$C$16,$C$15,$C$14)) -> 23.65 | M38: =IF(M$34<$C$17,0,IF(M$34>=$C$16,$C$15,$C$14)) -> 23.65 | ... AC38: =IF(AC$34<$C$17,0,IF(AC$34>=$C$16,$C$15,$C$14)) -> 23.65
B39: Opening reserve | C39: Mt | F39: =$C$6-$C$7 -> 448.832 | G39: =F41 -> 427.332 | H39: =G41 -> 405.832 | I39: =H41 -> 382.182 | J39: =I41 -> 358.532 | K39: =J41 -> 334.882 | L39: =K41 -> 311.232 | M39: =L41 -> 287.582 | N39: =M41 -> 263.932 | ... AC39: =AB41 -> 0
B40: Ore processed | C40: Mt | D40: =SUM(F40:AC40) -> 448.832 | F40: =MAX(0,MIN(F38,F39)) -> 21.5 | G40: =MAX(0,MIN(G38,G39)) -> 21.5 | H40: =MAX(0,MIN(H38,H39)) -> 23.65 | I40: =MAX(0,MIN(I38,I39)) -> 23.65 | J40: =MAX(0,MIN(J38,J39)) -> 23.65 | K40: =MAX(0,MIN(K38,K39)) -> 23.65 | L40: =MAX(0,MIN(L38,L39)) -> 23.65 | M40: =MAX(0,MIN(M38,M39)) -> 23.65 | ... AC40: =MAX(0,MIN(AC38,AC39)) -> 0
B41: Closing reserve | C41: Mt | F41: =F39-F40 -> 427.332 | G41: =G39-G40 -> 405.832 | H41: =H39-H40 -> 382.182 | I41: =I39-I40 -> 358.532 | J41: =J39-J40 -> 334.882 | K41: =K39-K40 -> 311.232 | L41: =L39-L40 -> 287.582 | M41: =M39-M40 -> 263.932 | ... AC41: =AC39-AC40 -> 0
B42: Payable copper | C42: Mlb | D42: =SUM(F42:AC42) -> 1222.2353 | F42: =F40*$C$8*$C$10*$C$12*2204.62 -> 58.547652 | G42: =G40*$C$8*$C$10*$C$12*2204.62 -> 58.547652 | H42: =H40*$C$8*$C$10*$C$12*2204.62 -> 64.402418 | I42: =I40*$C$8*$C$10*$C$12*2204.62 -> 64.402418 | J42: =J40*$C$8*$C$10*$C$12*2204.62 -> 64.402418 | K42: =K40*$C$8*$C$10*$C$12*2204.62 -> 64.402418 | L42: =L40*$C$8*$C$10*$C$12*2204.62 -> 64.402418 | M42: =M40*$C$8*$C$10*$C$12*2204.62 -> 64.402418 | ... AC42: =AC40*$C$8*$C$10*$C$12*2204.62 -> 0
B43: Payable gold | C43: koz | D43: =SUM(F43:AC43) -> 2508.3278 | F43: =F40*$C$9*$C$11*$C$13*1000/31.1035 -> 120.15419 | G43: =G40*$C$9*$C$11*$C$13*1000/31.1035 -> 120.15419 | H43: =H40*$C$9*$C$11*$C$13*1000/31.1035 -> 132.16961 | I43: =I40*$C$9*$C$11*$C$13*1000/31.1035 -> 132.16961 | J43: =J40*$C$9*$C$11*$C$13*1000/31.1035 -> 132.16961 | K43: =K40*$C$9*$C$11*$C$13*1000/31.1035 -> 132.16961 | L43: =L40*$C$9*$C$11*$C$13*1000/31.1035 -> 132.16961 | M43: =M40*$C$9*$C$11*$C$13*1000/31.1035 -> 132.16961 | ... AC43: =AC40*$C$9*$C$11*$C$13*1000/31.1035 -> 0
B44: Realised copper price (after stream) | C44: US$/lb | F44: =F36*(1-$C$29)+F36*$C$29*$C$30 -> 5.04375 | G44: =G36*(1-$C$29)+G36*$C$29*$C$30 -> 4.6234375 | H44: =H36*(1-$C$29)+H36*$C$29*$C$30 -> 4.203125 | I44: =I36*(1-$C$29)+I36*$C$29*$C$30 -> 4.203125 | J44: =J36*(1-$C$29)+J36*$C$29*$C$30 -> 4.203125 | K44: =K36*(1-$C$29)+K36*$C$29*$C$30 -> 4.203125 | L44: =L36*(1-$C$29)+L36*$C$29*$C$30 -> 4.203125 | M44: =M36*(1-$C$29)+M36*$C$29*$C$30 -> 4.203125 | ... AC44: =AC36*(1-$C$29)+AC36*$C$29*$C$30 -> 4.203125
B45: Realised gold price (after stream) | C45: US$/oz | F45: =F37*(1-$C$27)+$C$27*$C$28 -> 2687.25 | G45: =G37*(1-$C$27)+$C$27*$C$28 -> 2492.25 | H45: =H37*(1-$C$27)+$C$27*$C$28 -> 2297.25 | I45: =I37*(1-$C$27)+$C$27*$C$28 -> 2297.25 | J45: =J37*(1-$C$27)+$C$27*$C$28 -> 2297.25 | K45: =K37*(1-$C$27)+$C$27*$C$28 -> 2297.25 | L45: =L37*(1-$C$27)+$C$27*$C$28 -> 2297.25 | M45: =M37*(1-$C$27)+$C$27*$C$28 -> 2297.25 | ... AC45: =AC37*(1-$C$27)+$C$27*$C$28 -> 2297.25
B46: Copper revenue | C46: US$M | D46: =SUM(F46:AC46) -> 5211.0329 | F46: =F42*F44 -> 295.29972 | G46: =G42*G44 -> 270.69141 | H46: =H42*H44 -> 270.69141 | I46: =I42*I44 -> 270.69141 | J46: =J42*J44 -> 270.69141 | K46: =K42*K44 -> 270.69141 | L46: =L42*L44 -> 270.69141 | M46: =M42*M44 -> 270.69141 | ... AC46: =AC42*AC44 -> 0
B47: Gold revenue | C47: US$M | D47: =SUM(F47:AC47) -> 5832.5462 | F47: =F43*F45/1000 -> 322.88436 | G47: =G43*G45/1000 -> 299.45429 | H47: =H43*H45/1000 -> 303.62665 | I47: =I43*I45/1000 -> 303.62665 | J47: =J43*J45/1000 -> 303.62665 | K47: =K43*K45/1000 -> 303.62665 | L47: =L43*L45/1000 -> 303.62665 | M47: =M43*M45/1000 -> 303.62665 | ... AC47: =AC43*AC45/1000 -> 0
B48: Total revenue | C48: US$M | D48: =SUM(F48:AC48) -> 11043.579 | F48: =F46+F47 -> 618.18408 | G48: =G46+G47 -> 570.1457 | H48: =H46+H47 -> 574.31806 | I48: =I46+I47 -> 574.31806 | J48: =J46+J47 -> 574.31806 | K48: =K46+K47 -> 574.31806 | L48: =L46+L47 -> 574.31806 | M48: =M46+M47 -> 574.31806 | ... AC48: =AC46+AC47 -> 0
B49: TC/RC and freight | C49: US$M | D49: =SUM(F49:AC49) -> -550.00591 | F49: =-F42*$C$19 -> -26.346444 | G49: =-G42*$C$19 -> -26.346444 | H49: =-H42*$C$19 -> -28.981088 | I49: =-I42*$C$19 -> -28.981088 | J49: =-J42*$C$19 -> -28.981088 | K49: =-K42*$C$19 -> -28.981088 | L49: =-L42*$C$19 -> -28.981088 | M49: =-M42*$C$19 -> -28.981088 | ... AC49: =-AC42*$C$19 -> 0
...

Sheet Oksut
B1: Öksüt — asset NAV (CG, Türkiye)
B2: Reserve-constrained life-of-mine model. Blue = input (data/assets.csv), green = link, black = formula. US$M real unless noted.
B4: Input | C4: Value | D4: Unit | F4: Source / status
B5: Ownership | C5: 1 | D5: % | F5: Source IDs: CG-MRMR-2025;CG-Q2-2026 (see Sources tab)
B6: P&P reserve (at effective date) | C6: 15.355 | D6: Mt | F6: [verified] reserve_mt|au_gpt: Year-end 2025 P&P 15.4 Mt @ 1.02 g/t Au
B7: Depletion to 1 Jan 2027 | C7: 5 | D7: Mt | F7: [calibrated] nsr_royalty|opex_usd_t: Set so AISC lands in the US$1,850–1,950/oz 2026 guidance range (includes state royalty)
B8: Copper grade | C8: 0 | D8: % Cu
B9: Gold grade | C9: 1.02 | D9: g/t Au
B10: Copper recovery | C10: 0 | D10: %
B11: Gold recovery | C11: 0.78 | D11: %
B12: Copper payable | C12: 0 | D12: %
B13: Gold payable | C13: 0.999 | D13: %
B14: Throughput | C14: 4.5 | D14: Mtpa
B15: Throughput after expansion | C15: 4.5 | D15: Mtpa
B16: Expansion year | C16: 2027 | D16: year
B17: First production year | C17: 2027 | D17: year
B18: Site operating cost | C18: 36 | D18: US$/t milled
B19: TC/RC and freight | C19: 0 | D19: US$/lb Cu
... B30: Stream copper price received | C30: 0 | D30: % of spot
B31: Discount rate (real) | C31: =Inputs!$C$23 -> 0.05 | D31: Inputs tab
B34: US$M unless noted | C34: Unit | D34: LOM / NPV | F34: 2027 | G34: 2028 | H34: 2029 | I34: 2030 | J34: 2031 | K34: 2032 | L34: 2033 | M34: 2034 | N34: 2035 | O34: 2036 | P34: 2037 | Q34: 2038 | R34: 2039 | S34: 2040 | T34: 2041 | U34: 2042 | V34: 2043 | W34: 2044 | X34: 2045 | Y34: 2046 | Z34: 2047 | AA34: 2048 | AB34: 2049 | AC34: 2050
B35: Period | F35: =F$34-2027+1 -> 1 | G35: =G$34-2027+1 -> 2 | H35: =H$34-2027+1 -> 3 | I35: =I$34-2027+1 -> 4 | J35: =J$34-2027+1 -> 5 | K35: =K$34-2027+1 -> 6 | L35: =L$34-2027+1 -> 7 | M35: =M$34-2027+1 -> 8 | ... AC35: =AC$34-2027+1 -> 24
B36: Copper price | C36: US$/lb | F36: =Inputs!F$18 -> 6 | G36: =Inputs!G$18 -> 5.5 | H36: =Inputs!H$18 -> 5 | I36: =Inputs!I$18 -> 5 | J36: =Inputs!J$18 -> 5 | K36: =Inputs!K$18 -> 5 | L36: =Inputs!L$18 -> 5 | M36: =Inputs!M$18 -> 5 | ... AC36: =Inputs!AC$18 -> 5
B37: Gold price | C37: US$/oz | F37: =Inputs!F$19 -> 3900 | G37: =Inputs!G$19 -> 3600 | H37: =Inputs!H$19 -> 3300 | I37: =Inputs!I$19 -> 3300 | J37: =Inputs!J$19 -> 3300 | K37: =Inputs!K$19 -> 3300 | L37: =Inputs!L$19 -> 3300 | M37: =Inputs!M$19 -> 3300 | ... AC37: =Inputs!AC$19 -> 3300
B38: Mill capacity | C38: Mt | F38: =IF(F$34<$C$17,0,IF(F$34>=$C$16,$C$15,$C$14)) -> 4.5 | G38: =IF(G$34<$C$17,0,IF(G$34>=$C$16,$C$15,$C$14)) -> 4.5 | H38: =IF(H$34<$C$17,0,IF(H$34>=$C$16,$C$15,$C$14)) -> 4.5 | I38: =IF(I$34<$C$17,0,IF(I$34>=$C$16,$C$15,$C$14)) -> 4.5 | J38: =IF(J$34<$C$17,0,IF(J$34>=$C$16,$C$15,$C$14)) -> 4.5 | K38: =IF(K$34<$C$17,0,IF(K$34>=$C$16,$C$15,$C$14)) -> 4.5 | L38: =IF(L$34<$C$17,0,IF(L$34>=$C$16,$C$15,$C$14)) -> 4.5 | M38: =IF(M$34<$C$17,0,IF(M$34>=$C$16,$C$15,$C$14)) -> 4.5 | ... AC38: =IF(AC$34<$C$17,0,IF(AC$34>=$C$16,$C$15,$C$14)) -> 4.5
B39: Opening reserve | C39: Mt | F39: =$C$6-$C$7 -> 10.355 | G39: =F41 -> 5.855 | H39: =G41 -> 1.355 | I39: =H41 -> 0 | J39: =I41 -> 0 | K39: =J41 -> 0 | L39: =K41 -> 0 | M39: =L41 -> 0 | N39: =M41 -> 0 | ... AC39: =AB41 -> 0
B40: Ore processed | C40: Mt | D40: =SUM(F40:AC40) -> 10.355 | F40: =MAX(0,MIN(F38,F39)) -> 4.5 | G40: =MAX(0,MIN(G38,G39)) -> 4.5 | H40: =MAX(0,MIN(H38,H39)) -> 1.355 | I40: =MAX(0,MIN(I38,I39)) -> 0 | J40: =MAX(0,MIN(J38,J39)) -> 0 | K40: =MAX(0,MIN(K38,K39)) -> 0 | L40: =MAX(0,MIN(L38,L39)) -> 0 | M40: =MAX(0,MIN(M38,M39)) -> 0 | ... AC40: =MAX(0,MIN(AC38,AC39)) -> 0
B41: Closing reserve | C41: Mt | F41: =F39-F40 -> 5.855 | G41: =G39-G40 -> 1.355 | H41: =H39-H40 -> 0 | I41: =I39-I40 -> 0 | J41: =J39-J40 -> 0 | K41: =K39-K40 -> 0 | L41: =L39-L40 -> 0 | M41: =M39-M40 -> 0 | ... AC41: =AC39-AC40 -> 0
B42: Payable copper | C42: Mlb | D42: =SUM(F42:AC42) -> 0 | F42: =F40*$C$8*$C$10*$C$12*2204.62 -> 0 | G42: =G40*$C$8*$C$10*$C$12*2204.62 -> 0 | H42: =H40*$C$8*$C$10*$C$12*2204.62 -> 0 | I42: =I40*$C$8*$C$10*$C$12*2204.62 -> 0 | J42: =J40*$C$8*$C$10*$C$12*2204.62 -> 0 | K42: =K40*$C$8*$C$10*$C$12*2204.62 -> 0 | L42: =L40*$C$8*$C$10*$C$12*2204.62 -> 0 | M42: =M40*$C$8*$C$10*$C$12*2204.62 -> 0 | ... AC42: =AC40*$C$8*$C$10*$C$12*2204.62 -> 0
B43: Payable gold | C43: koz | D43: =SUM(F43:AC43) -> 264.60686 | F43: =F40*$C$9*$C$11*$C$13*1000/31.1035 -> 114.99091 | G43: =G40*$C$9*$C$11*$C$13*1000/31.1035 -> 114.99091 | H43: =H40*$C$9*$C$11*$C$13*1000/31.1035 -> 34.625041 | I43: =I40*$C$9*$C$11*$C$13*1000/31.1035 -> 0 | J43: =J40*$C$9*$C$11*$C$13*1000/31.1035 -> 0 | K43: =K40*$C$9*$C$11*$C$13*1000/31.1035 -> 0 | L43: =L40*$C$9*$C$11*$C$13*1000/31.1035 -> 0 | M43: =M40*$C$9*$C$11*$C$13*1000/31.1035 -> 0 | ... AC43: =AC40*$C$9*$C$11*$C$13*1000/31.1035 -> 0
B44: Realised copper price (after stream) | C44: US$/lb | F44: =F36*(1-$C$29)+F36*$C$29*$C$30 -> 6 | G44: =G36*(1-$C$29)+G36*$C$29*$C$30 -> 5.5 | H44: =H36*(1-$C$29)+H36*$C$29*$C$30 -> 5 | I44: =I36*(1-$C$29)+I36*$C$29*$C$30 -> 5 | J44: =J36*(1-$C$29)+J36*$C$29*$C$30 -> 5 | K44: =K36*(1-$C$29)+K36*$C$29*$C$30 -> 5 | L44: =L36*(1-$C$29)+L36*$C$29*$C$30 -> 5 | M44: =M36*(1-$C$29)+M36*$C$29*$C$30 -> 5 | ... AC44: =AC36*(1-$C$29)+AC36*$C$29*$C$30 -> 5
B45: Realised gold price (after stream) | C45: US$/oz | F45: =F37*(1-$C$27)+$C$27*$C$28 -> 3900 | G45: =G37*(1-$C$27)+$C$27*$C$28 -> 3600 | H45: =H37*(1-$C$27)+$C$27*$C$28 -> 3300 | I45: =I37*(1-$C$27)+$C$27*$C$28 -> 3300 | J45: =J37*(1-$C$27)+$C$27*$C$28 -> 3300 | K45: =K37*(1-$C$27)+$C$27*$C$28 -> 3300 | L45: =L37*(1-$C$27)+$C$27*$C$28 -> 3300 | M45: =M37*(1-$C$27)+$C$27*$C$28 -> 3300 | ... AC45: =AC37*(1-$C$27)+$C$27*$C$28 -> 3300
B46: Copper revenue | C46: US$M | D46: =SUM(F46:AC46) -> 0 | F46: =F42*F44 -> 0 | G46: =G42*G44 -> 0 | H46: =H42*H44 -> 0 | I46: =I42*I44 -> 0 | J46: =J42*J44 -> 0 | K46: =K42*K44 -> 0 | L46: =L42*L44 -> 0 | M46: =M42*M44 -> 0 | ... AC46: =AC42*AC44 -> 0
B47: Gold revenue | C47: US$M | D47: =SUM(F47:AC47) -> 976.69447 | F47: =F43*F45/1000 -> 448.46455 | G47: =G43*G45/1000 -> 413.96728 | H47: =H43*H45/1000 -> 114.26264 | I47: =I43*I45/1000 -> 0 | J47: =J43*J45/1000 -> 0 | K47: =K43*K45/1000 -> 0 | L47: =L43*L45/1000 -> 0 | M47: =M43*M45/1000 -> 0 | ... AC47: =AC43*AC45/1000 -> 0
B48: Total revenue | C48: US$M | D48: =SUM(F48:AC48) -> 976.69447 | F48: =F46+F47 -> 448.46455 | G48: =G46+G47 -> 413.96728 | H48: =H46+H47 -> 114.26264 | I48: =I46+I47 -> 0 | J48: =J46+J47 -> 0 | K48: =K46+K47 -> 0 | L48: =L46+L47 -> 0 | M48: =M46+M47 -> 0 | ... AC48: =AC46+AC47 -> 0
B49: TC/RC and freight | C49: US$M | D49: =SUM(F49:AC49) -> 0 | F49: =-F42*$C$19 -> 0 | G49: =-G42*$C$19 -> 0 | H49: =-H42*$C$19 -> 0 | I49: =-I42*$C$19 -> 0 | J49: =-J42*$C$19 -> 0 | K49: =-K42*$C$19 -> 0 | L49: =-L42*$C$19 -> 0 | M49: =-M42*$C$19 -> 0 | ... AC49: =-AC42*$C$19 -> 0
B50: Royalties | C50: US$M | D50: =SUM(F50:AC50) -> -78.135557 | F50: =-F48*$C$25 -> -35.877164 | G50: =-G48*$C$25 -> -33.117382 | H50: =-H48*$C$25 -> -9.1410108 | I50: =-I48*$C$25 -> 0 | J50: =-J48*$C$25 -> 0 | K50: =-K48*$C$25 -> 0 | L50: =-L48*$C$25 -> 0 | M50: =-M48*$C$25 -> 0 | ... AC50: =-AC48*$C$25 -> 0
B51: Site operating costs | C51: US$M | D51: =SUM(F51:AC51) -> -372.78 | F51: =-F40*$C$18 -> -162 | G51: =-G40*$C$18 -> -162 | H51: =-H40*$C$18 -> -48.78 | I51: =-I40*$C$18 -> 0 | J51: =-J40*$C$18 -> 0 | K51: =-K40*$C$18 -> 0 | L51: =-L40*$C$18 -> 0 | M51: =-M40*$C$18 -> 0 | ... AC51: =-AC40*$C$18 -> 0
B52: Mine EBITDA | C52: US$M | D52: =SUM(F52:AC52) -> 525.77891 | F52: =SUM(F48:F51) -> 250.58739 | G52: =SUM(G48:G51) -> 218.8499 | H52: =SUM(H48:H51) -> 56.341624 | I52: =SUM(I48:I51) -> 0 | J52: =SUM(J48:J51) -> 0 | K52: =SUM(K48:K51) -> 0 | L52: =SUM(L48:L51) -> 0 | M52: =SUM(M48:M51) -> 0 | ... AC52: =SUM(AC48:AC51) -> 0
B53: Sustaining capex | C53: US$M | D53: =SUM(F53:AC53) -> -60 | F53: =-IF(F40>0,$C$20,0) -> -20 | G53: =-IF(G40>0,$C$20,0) -> -20 | H53: =-IF(H40>0,$C$20,0) -> -20 | I53: =-IF(I40>0,$C$20,0) -> 0 | J53: =-IF(J40>0,$C$20,0) -> 0 | K53: =-IF(K40>0,$C$20,0) -> 0 | L53: =-IF(L40>0,$C$20,0) -> 0 | M53: =-IF(M40>0,$C$20,0) -> 0 | ... AC53: =-IF(AC40>0,$C$20,0) -> 0
...

Sheet Goldfield
B1: Goldfield — asset NAV (CG, US (Nevada))
B2: Reserve-constrained life-of-mine model. Blue = input (data/assets.csv), green = link, black = formula. US$M real unless noted.
B4: Input | C4: Value | D4: Unit | F4: Source / status
B5: Ownership | C5: 1 | D5: % | F5: Source IDs: CG-MRMR-2025 (see Sources tab)
B6: P&P reserve (at effective date) | C6: 33.348 | D6: Mt | F6: [verified] reserve_mt|au_gpt: Year-end 2025 P&P 33.3 Mt @ 0.66 g/t Au (maiden reserve)
B7: Depletion to 1 Jan 2027 | C7: 0 | D7: Mt | F7: [estimate] growth_capex_usd_m|start_year|throughput_mtpa: Development schedule and capex are analyst estimates pending a construction decision
B8: Copper grade | C8: 0 | D8: % Cu
B9: Gold grade | C9: 0.66 | D9: g/t Au
B10: Copper recovery | C10: 0 | D10: %
B11: Gold recovery | C11: 0.72 | D11: %
B12: Copper payable | C12: 0 | D12: %
B13: Gold payable | C13: 0.999 | D13: %
B14: Throughput | C14: 4.5 | D14: Mtpa
B15: Throughput after expansion | C15: 4.5 | D15: Mtpa
B16: Expansion year | C16: 2029 | D16: year
B17: First production year | C17: 2029 | D17: year
B18: Site operating cost | C18: 19 | D18: US$/t milled
B19: TC/RC and freight | C19: 0 | D19: US$/lb Cu
... B30: Stream copper price received | C30: 0 | D30: % of spot
B31: Discount rate (real) | C31: =Inputs!$C$24 -> 0.05 | D31: Inputs tab
B34: US$M unless noted | C34: Unit | D34: LOM / NPV | F34: 2027 | G34: 2028 | H34: 2029 | I34: 2030 | J34: 2031 | K34: 2032 | L34: 2033 | M34: 2034 | N34: 2035 | O34: 2036 | P34: 2037 | Q34: 2038 | R34: 2039 | S34: 2040 | T34: 2041 | U34: 2042 | V34: 2043 | W34: 2044 | X34: 2045 | Y34: 2046 | Z34: 2047 | AA34: 2048 | AB34: 2049 | AC34: 2050
B35: Period | F35: =F$34-2027+1 -> 1 | G35: =G$34-2027+1 -> 2 | H35: =H$34-2027+1 -> 3 | I35: =I$34-2027+1 -> 4 | J35: =J$34-2027+1 -> 5 | K35: =K$34-2027+1 -> 6 | L35: =L$34-2027+1 -> 7 | M35: =M$34-2027+1 -> 8 | ... AC35: =AC$34-2027+1 -> 24
B36: Copper price | C36: US$/lb | F36: =Inputs!F$18 -> 6 | G36: =Inputs!G$18 -> 5.5 | H36: =Inputs!H$18 -> 5 | I36: =Inputs!I$18 -> 5 | J36: =Inputs!J$18 -> 5 | K36: =Inputs!K$18 -> 5 | L36: =Inputs!L$18 -> 5 | M36: =Inputs!M$18 -> 5 | ... AC36: =Inputs!AC$18 -> 5
B37: Gold price | C37: US$/oz | F37: =Inputs!F$19 -> 3900 | G37: =Inputs!G$19 -> 3600 | H37: =Inputs!H$19 -> 3300 | I37: =Inputs!I$19 -> 3300 | J37: =Inputs!J$19 -> 3300 | K37: =Inputs!K$19 -> 3300 | L37: =Inputs!L$19 -> 3300 | M37: =Inputs!M$19 -> 3300 | ... AC37: =Inputs!AC$19 -> 3300
B38: Mill capacity | C38: Mt | F38: =IF(F$34<$C$17,0,IF(F$34>=$C$16,$C$15,$C$14)) -> 0 | G38: =IF(G$34<$C$17,0,IF(G$34>=$C$16,$C$15,$C$14)) -> 0 | H38: =IF(H$34<$C$17,0,IF(H$34>=$C$16,$C$15,$C$14)) -> 4.5 | I38: =IF(I$34<$C$17,0,IF(I$34>=$C$16,$C$15,$C$14)) -> 4.5 | J38: =IF(J$34<$C$17,0,IF(J$34>=$C$16,$C$15,$C$14)) -> 4.5 | K38: =IF(K$34<$C$17,0,IF(K$34>=$C$16,$C$15,$C$14)) -> 4.5 | L38: =IF(L$34<$C$17,0,IF(L$34>=$C$16,$C$15,$C$14)) -> 4.5 | M38: =IF(M$34<$C$17,0,IF(M$34>=$C$16,$C$15,$C$14)) -> 4.5 | ... AC38: =IF(AC$34<$C$17,0,IF(AC$34>=$C$16,$C$15,$C$14)) -> 4.5
B39: Opening reserve | C39: Mt | F39: =$C$6-$C$7 -> 33.348 | G39: =F41 -> 33.348 | H39: =G41 -> 33.348 | I39: =H41 -> 28.848 | J39: =I41 -> 24.348 | K39: =J41 -> 19.848 | L39: =K41 -> 15.348 | M39: =L41 -> 10.848 | N39: =M41 -> 6.348 | ... AC39: =AB41 -> 0
B40: Ore processed | C40: Mt | D40: =SUM(F40:AC40) -> 33.348 | F40: =MAX(0,MIN(F38,F39)) -> 0 | G40: =MAX(0,MIN(G38,G39)) -> 0 | H40: =MAX(0,MIN(H38,H39)) -> 4.5 | I40: =MAX(0,MIN(I38,I39)) -> 4.5 | J40: =MAX(0,MIN(J38,J39)) -> 4.5 | K40: =MAX(0,MIN(K38,K39)) -> 4.5 | L40: =MAX(0,MIN(L38,L39)) -> 4.5 | M40: =MAX(0,MIN(M38,M39)) -> 4.5 | ... AC40: =MAX(0,MIN(AC38,AC39)) -> 0
B41: Closing reserve | C41: Mt | F41: =F39-F40 -> 33.348 | G41: =G39-G40 -> 33.348 | H41: =H39-H40 -> 28.848 | I41: =I39-I40 -> 24.348 | J41: =J39-J40 -> 19.848 | K41: =K39-K40 -> 15.348 | L41: =L39-L40 -> 10.848 | M41: =M39-M40 -> 6.348 | ... AC41: =AC39-AC40 -> 0
B42: Payable copper | C42: Mlb | D42: =SUM(F42:AC42) -> 0 | F42: =F40*$C$8*$C$10*$C$12*2204.62 -> 0 | G42: =G40*$C$8*$C$10*$C$12*2204.62 -> 0 | H42: =H40*$C$8*$C$10*$C$12*2204.62 -> 0 | I42: =I40*$C$8*$C$10*$C$12*2204.62 -> 0 | J42: =J40*$C$8*$C$10*$C$12*2204.62 -> 0 | K42: =K40*$C$8*$C$10*$C$12*2204.62 -> 0 | L42: =L40*$C$8*$C$10*$C$12*2204.62 -> 0 | M42: =M40*$C$8*$C$10*$C$12*2204.62 -> 0 | ... AC42: =AC40*$C$8*$C$10*$C$12*2204.62 -> 0
B43: Payable gold | C43: koz | D43: =SUM(F43:AC43) -> 508.98203 | F43: =F40*$C$9*$C$11*$C$13*1000/31.1035 -> 0 | G43: =G40*$C$9*$C$11*$C$13*1000/31.1035 -> 0 | H43: =H40*$C$9*$C$11*$C$13*1000/31.1035 -> 68.682354 | I43: =I40*$C$9*$C$11*$C$13*1000/31.1035 -> 68.682354 | J43: =J40*$C$9*$C$11*$C$13*1000/31.1035 -> 68.682354 | K43: =K40*$C$9*$C$11*$C$13*1000/31.1035 -> 68.682354 | L43: =L40*$C$9*$C$11*$C$13*1000/31.1035 -> 68.682354 | M43: =M40*$C$9*$C$11*$C$13*1000/31.1035 -> 68.682354 | ... AC43: =AC40*$C$9*$C$11*$C$13*1000/31.1035 -> 0
B44: Realised copper price (after stream) | C44: US$/lb | F44: =F36*(1-$C$29)+F36*$C$29*$C$30 -> 6 | G44: =G36*(1-$C$29)+G36*$C$29*$C$30 -> 5.5 | H44: =H36*(1-$C$29)+H36*$C$29*$C$30 -> 5 | I44: =I36*(1-$C$29)+I36*$C$29*$C$30 -> 5 | J44: =J36*(1-$C$29)+J36*$C$29*$C$30 -> 5 | K44: =K36*(1-$C$29)+K36*$C$29*$C$30 -> 5 | L44: =L36*(1-$C$29)+L36*$C$29*$C$30 -> 5 | M44: =M36*(1-$C$29)+M36*$C$29*$C$30 -> 5 | ... AC44: =AC36*(1-$C$29)+AC36*$C$29*$C$30 -> 5
B45: Realised gold price (after stream) | C45: US$/oz | F45: =F37*(1-$C$27)+$C$27*$C$28 -> 3900 | G45: =G37*(1-$C$27)+$C$27*$C$28 -> 3600 | H45: =H37*(1-$C$27)+$C$27*$C$28 -> 3300 | I45: =I37*(1-$C$27)+$C$27*$C$28 -> 3300 | J45: =J37*(1-$C$27)+$C$27*$C$28 -> 3300 | K45: =K37*(1-$C$27)+$C$27*$C$28 -> 3300 | L45: =L37*(1-$C$27)+$C$27*$C$28 -> 3300 | M45: =M37*(1-$C$27)+$C$27*$C$28 -> 3300 | ... AC45: =AC37*(1-$C$27)+$C$27*$C$28 -> 3300
B46: Copper revenue | C46: US$M | D46: =SUM(F46:AC46) -> 0 | F46: =F42*F44 -> 0 | G46: =G42*G44 -> 0 | H46: =H42*H44 -> 0 | I46: =I42*I44 -> 0 | J46: =J42*J44 -> 0 | K46: =K42*K44 -> 0 | L46: =L42*L44 -> 0 | M46: =M42*M44 -> 0 | ... AC46: =AC42*AC44 -> 0
B47: Gold revenue | C47: US$M | D47: =SUM(F47:AC47) -> 1679.6407 | F47: =F43*F45/1000 -> 0 | G47: =G43*G45/1000 -> 0 | H47: =H43*H45/1000 -> 226.65177 | I47: =I43*I45/1000 -> 226.65177 | J47: =J43*J45/1000 -> 226.65177 | K47: =K43*K45/1000 -> 226.65177 | L47: =L43*L45/1000 -> 226.65177 | M47: =M43*M45/1000 -> 226.65177 | ... AC47: =AC43*AC45/1000 -> 0
B48: Total revenue | C48: US$M | D48: =SUM(F48:AC48) -> 1679.6407 | F48: =F46+F47 -> 0 | G48: =G46+G47 -> 0 | H48: =H46+H47 -> 226.65177 | I48: =I46+I47 -> 226.65177 | J48: =J46+J47 -> 226.65177 | K48: =K46+K47 -> 226.65177 | L48: =L46+L47 -> 226.65177 | M48: =M46+M47 -> 226.65177 | ... AC48: =AC46+AC47 -> 0
B49: TC/RC and freight | C49: US$M | D49: =SUM(F49:AC49) -> 0 | F49: =-F42*$C$19 -> 0 | G49: =-G42*$C$19 -> 0 | H49: =-H42*$C$19 -> 0 | I49: =-I42*$C$19 -> 0 | J49: =-J42*$C$19 -> 0 | K49: =-K42*$C$19 -> 0 | L49: =-L42*$C$19 -> 0 | M49: =-M42*$C$19 -> 0 | ... AC49: =-AC42*$C$19 -> 0
B50: Royalties | C50: US$M | D50: =SUM(F50:AC50) -> -41.991018 | F50: =-F48*$C$25 -> 0 | G50: =-G48*$C$25 -> 0 | H50: =-H48*$C$25 -> -5.6662942 | I50: =-I48*$C$25 -> -5.6662942 | J50: =-J48*$C$25 -> -5.6662942 | K50: =-K48*$C$25 -> -5.6662942 | L50: =-L48*$C$25 -> -5.6662942 | M50: =-M48*$C$25 -> -5.6662942 | ... AC50: =-AC48*$C$25 -> 0
B51: Site operating costs | C51: US$M | D51: =SUM(F51:AC51) -> -633.612 | F51: =-F40*$C$18 -> 0 | G51: =-G40*$C$18 -> 0 | H51: =-H40*$C$18 -> -85.5 | I51: =-I40*$C$18 -> -85.5 | J51: =-J40*$C$18 -> -85.5 | K51: =-K40*$C$18 -> -85.5 | L51: =-L40*$C$18 -> -85.5 | M51: =-M40*$C$18 -> -85.5 | ... AC51: =-AC40*$C$18 -> 0
B52: Mine EBITDA | C52: US$M | D52: =SUM(F52:AC52) -> 1004.0377 | F52: =SUM(F48:F51) -> 0 | G52: =SUM(G48:G51) -> 0 | H52: =SUM(H48:H51) -> 135.48547 | I52: =SUM(I48:I51) -> 135.48547 | J52: =SUM(J48:J51) -> 135.48547 | K52: =SUM(K48:K51) -> 135.48547 | L52: =SUM(L48:L51) -> 135.48547 | M52: =SUM(M48:M51) -> 135.48547 | ... AC52: =SUM(AC48:AC51) -> 0
B53: Sustaining capex | C53: US$M | D53: =SUM(F53:AC53) -> -120 | F53: =-IF(F40>0,$C$20,0) -> 0 | G53: =-IF(G40>0,$C$20,0) -> 0 | H53: =-IF(H40>0,$C$20,0) -> -15 | I53: =-IF(I40>0,$C$20,0) -> -15 | J53: =-IF(J40>0,$C$20,0) -> -15 | K53: =-IF(K40>0,$C$20,0) -> -15 | L53: =-IF(L40>0,$C$20,0) -> -15 | M53: =-IF(M40>0,$C$20,0) -> -15 | ... AC53: =-IF(AC40>0,$C$20,0) -> 0
...

Sheet Caraiba
B1: Caraíba — asset NAV (ERO, Brazil (Bahia))
B2: Reserve-constrained life-of-mine model. Blue = input (data/assets.csv), green = link, black = formula. US$M real unless noted.
B4: Input | C4: Value | D4: Unit | F4: Source / status
B5: Ownership | C5: 1 | D5: % | F5: Source IDs: ERO-CARAIBA-OPS;ERO-MDA-2025Q4;ERO-AIF-2025 (see Sources tab)
B6: P&P reserve (at effective date) | C6: 73.058 | D6: Mt | F6: [verified] reserve_mt|cu_grade_pct: Dec 2024 P&P: UG 30.9 Mt @ 1.38% + OP 42.2 Mt @ 0.54% = 73.1 Mt @ 0.90% Cu
B7: Depletion to 1 Jan 2027 | C7: 3.9 | D7: Mt | F7: [estimate] depleted_mt: 2025 processed 3.66 Mt (verified); 2026 assumed ~3.9 Mt; 2025 depletion netted against grade conservatism
B8: Copper grade | C8: 0.00895 | D8: % Cu | F8: [calibrated] opex_usd_t|tcrc_usd_lb: Set so C1 lands near the US$2.30–2.50/lb 2026 guidance
B9: Gold grade | C9: 0 | D9: g/t Au | F9: [calibrated] sustaining_usd_m: Set so AISC lands near US$3.25/lb (C1 plus sustaining capex and royalties)
B10: Copper recovery | C10: 0.91 | D10: %
B11: Gold recovery | C11: 0 | D11: %
B12: Copper payable | C12: 0.965 | D12: %
B13: Gold payable | C13: 0 | D13: %
B14: Throughput | C14: 4.2 | D14: Mtpa
B15: Throughput after expansion | C15: 4.2 | D15: Mtpa
B16: Expansion year | C16: 2027 | D16: year
B17: First production year | C17: 2027 | D17: year
B18: Site operating cost | C18: 37 | D18: US$/t milled
B19: TC/RC and freight | C19: 0.35 | D19: US$/lb Cu
B20: Sustaining capex | C20: 55 | D20: US$M/yr
B21: Growth capex (total) | C21: 60 | D21: US$M
... B30: Stream copper price received | C30: 0 | D30: % of spot
B31: Discount rate (real) | C31: =Inputs!$C$25 -> 0.08 | D31: Inputs tab
B34: US$M unless noted | C34: Unit | D34: LOM / NPV | F34: 2027 | G34: 2028 | H34: 2029 | I34: 2030 | J34: 2031 | K34: 2032 | L34: 2033 | M34: 2034 | N34: 2035 | O34: 2036 | P34: 2037 | Q34: 2038 | R34: 2039 | S34: 2040 | T34: 2041 | U34: 2042 | V34: 2043 | W34: 2044 | X34: 2045 | Y34: 2046 | Z34: 2047 | AA34: 2048 | AB34: 2049 | AC34: 2050
B35: Period | F35: =F$34-2027+1 -> 1 | G35: =G$34-2027+1 -> 2 | H35: =H$34-2027+1 -> 3 | I35: =I$34-2027+1 -> 4 | J35: =J$34-2027+1 -> 5 | K35: =K$34-2027+1 -> 6 | L35: =L$34-2027+1 -> 7 | M35: =M$34-2027+1 -> 8 | ... AC35: =AC$34-2027+1 -> 24
B36: Copper price | C36: US$/lb | F36: =Inputs!F$18 -> 6 | G36: =Inputs!G$18 -> 5.5 | H36: =Inputs!H$18 -> 5 | I36: =Inputs!I$18 -> 5 | J36: =Inputs!J$18 -> 5 | K36: =Inputs!K$18 -> 5 | L36: =Inputs!L$18 -> 5 | M36: =Inputs!M$18 -> 5 | ... AC36: =Inputs!AC$18 -> 5
B37: Gold price | C37: US$/oz | F37: =Inputs!F$19 -> 3900 | G37: =Inputs!G$19 -> 3600 | H37: =Inputs!H$19 -> 3300 | I37: =Inputs!I$19 -> 3300 | J37: =Inputs!J$19 -> 3300 | K37: =Inputs!K$19 -> 3300 | L37: =Inputs!L$19 -> 3300 | M37: =Inputs!M$19 -> 3300 | ... AC37: =Inputs!AC$19 -> 3300
B38: Mill capacity | C38: Mt | F38: =IF(F$34<$C$17,0,IF(F$34>=$C$16,$C$15,$C$14)) -> 4.2 | G38: =IF(G$34<$C$17,0,IF(G$34>=$C$16,$C$15,$C$14)) -> 4.2 | H38: =IF(H$34<$C$17,0,IF(H$34>=$C$16,$C$15,$C$14)) -> 4.2 | I38: =IF(I$34<$C$17,0,IF(I$34>=$C$16,$C$15,$C$14)) -> 4.2 | J38: =IF(J$34<$C$17,0,IF(J$34>=$C$16,$C$15,$C$14)) -> 4.2 | K38: =IF(K$34<$C$17,0,IF(K$34>=$C$16,$C$15,$C$14)) -> 4.2 | L38: =IF(L$34<$C$17,0,IF(L$34>=$C$16,$C$15,$C$14)) -> 4.2 | M38: =IF(M$34<$C$17,0,IF(M$34>=$C$16,$C$15,$C$14)) -> 4.2 | ... AC38: =IF(AC$34<$C$17,0,IF(AC$34>=$C$16,$C$15,$C$14)) -> 4.2
B39: Opening reserve | C39: Mt | F39: =$C$6-$C$7 -> 69.158 | G39: =F41 -> 64.958 | H39: =G41 -> 60.758 | I39: =H41 -> 56.558 | J39: =I41 -> 52.358 | K39: =J41 -> 48.158 | L39: =K41 -> 43.958 | M39: =L41 -> 39.758 | N39: =M41 -> 35.558 | ... AC39: =AB41 -> 0
B40: Ore processed | C40: Mt | D40: =SUM(F40:AC40) -> 69.158 | F40: =MAX(0,MIN(F38,F39)) -> 4.2 | G40: =MAX(0,MIN(G38,G39)) -> 4.2 | H40: =MAX(0,MIN(H38,H39)) -> 4.2 | I40: =MAX(0,MIN(I38,I39)) -> 4.2 | J40: =MAX(0,MIN(J38,J39)) -> 4.2 | K40: =MAX(0,MIN(K38,K39)) -> 4.2 | L40: =MAX(0,MIN(L38,L39)) -> 4.2 | M40: =MAX(0,MIN(M38,M39)) -> 4.2 | ... AC40: =MAX(0,MIN(AC38,AC39)) -> 0
B41: Closing reserve | C41: Mt | F41: =F39-F40 -> 64.958 | G41: =G39-G40 -> 60.758 | H41: =H39-H40 -> 56.558 | I41: =I39-I40 -> 52.358 | J41: =J39-J40 -> 48.158 | K41: =K39-K40 -> 43.958 | L41: =L39-L40 -> 39.758 | M41: =M39-M40 -> 35.558 | ... AC41: =AC39-AC40 -> 0
B42: Payable copper | C42: Mlb | D42: =SUM(F42:AC42) -> 1198.3065 | F42: =F40*$C$8*$C$10*$C$12*2204.62 -> 72.773753 | G42: =G40*$C$8*$C$10*$C$12*2204.62 -> 72.773753 | H42: =H40*$C$8*$C$10*$C$12*2204.62 -> 72.773753 | I42: =I40*$C$8*$C$10*$C$12*2204.62 -> 72.773753 | J42: =J40*$C$8*$C$10*$C$12*2204.62 -> 72.773753 | K42: =K40*$C$8*$C$10*$C$12*2204.62 -> 72.773753 | L42: =L40*$C$8*$C$10*$C$12*2204.62 -> 72.773753 | M42: =M40*$C$8*$C$10*$C$12*2204.62 -> 72.773753 | ... AC42: =AC40*$C$8*$C$10*$C$12*2204.62 -> 0
B43: Payable gold | C43: koz | D43: =SUM(F43:AC43) -> 0 | F43: =F40*$C$9*$C$11*$C$13*1000/31.1035 -> 0 | G43: =G40*$C$9*$C$11*$C$13*1000/31.1035 -> 0 | H43: =H40*$C$9*$C$11*$C$13*1000/31.1035 -> 0 | I43: =I40*$C$9*$C$11*$C$13*1000/31.1035 -> 0 | J43: =J40*$C$9*$C$11*$C$13*1000/31.1035 -> 0 | K43: =K40*$C$9*$C$11*$C$13*1000/31.1035 -> 0 | L43: =L40*$C$9*$C$11*$C$13*1000/31.1035 -> 0 | M43: =M40*$C$9*$C$11*$C$13*1000/31.1035 -> 0 | ... AC43: =AC40*$C$9*$C$11*$C$13*1000/31.1035 -> 0
B44: Realised copper price (after stream) | C44: US$/lb | F44: =F36*(1-$C$29)+F36*$C$29*$C$30 -> 6 | G44: =G36*(1-$C$29)+G36*$C$29*$C$30 -> 5.5 | H44: =H36*(1-$C$29)+H36*$C$29*$C$30 -> 5 | I44: =I36*(1-$C$29)+I36*$C$29*$C$30 -> 5 | J44: =J36*(1-$C$29)+J36*$C$29*$C$30 -> 5 | K44: =K36*(1-$C$29)+K36*$C$29*$C$30 -> 5 | L44: =L36*(1-$C$29)+L36*$C$29*$C$30 -> 5 | M44: =M36*(1-$C$29)+M36*$C$29*$C$30 -> 5 | ... AC44: =AC36*(1-$C$29)+AC36*$C$29*$C$30 -> 5
B45: Realised gold price (after stream) | C45: US$/oz | F45: =F37*(1-$C$27)+$C$27*$C$28 -> 3900 | G45: =G37*(1-$C$27)+$C$27*$C$28 -> 3600 | H45: =H37*(1-$C$27)+$C$27*$C$28 -> 3300 | I45: =I37*(1-$C$27)+$C$27*$C$28 -> 3300 | J45: =J37*(1-$C$27)+$C$27*$C$28 -> 3300 | K45: =K37*(1-$C$27)+$C$27*$C$28 -> 3300 | L45: =L37*(1-$C$27)+$C$27*$C$28 -> 3300 | M45: =M37*(1-$C$27)+$C$27*$C$28 -> 3300 | ... AC45: =AC37*(1-$C$27)+$C$27*$C$28 -> 3300
B46: Copper revenue | C46: US$M | D46: =SUM(F46:AC46) -> 6100.693 | F46: =F42*F44 -> 436.64252 | G46: =G42*G44 -> 400.25564 | H46: =H42*H44 -> 363.86877 | I46: =I42*I44 -> 363.86877 | J46: =J42*J44 -> 363.86877 | K46: =K42*K44 -> 363.86877 | L46: =L42*L44 -> 363.86877 | M46: =M42*M44 -> 363.86877 | ... AC46: =AC42*AC44 -> 0
B47: Gold revenue | C47: US$M | D47: =SUM(F47:AC47) -> 0 | F47: =F43*F45/1000 -> 0 | G47: =G43*G45/1000 -> 0 | H47: =H43*H45/1000 -> 0 | I47: =I43*I45/1000 -> 0 | J47: =J43*J45/1000 -> 0 | K47: =K43*K45/1000 -> 0 | L47: =L43*L45/1000 -> 0 | M47: =M43*M45/1000 -> 0 | ... AC47: =AC43*AC45/1000 -> 0
B48: Total revenue | C48: US$M | D48: =SUM(F48:AC48) -> 6100.693 | F48: =F46+F47 -> 436.64252 | G48: =G46+G47 -> 400.25564 | H48: =H46+H47 -> 363.86877 | I48: =I46+I47 -> 363.86877 | J48: =J46+J47 -> 363.86877 | K48: =K46+K47 -> 363.86877 | L48: =L46+L47 -> 363.86877 | M48: =M46+M47 -> 363.86877 | ... AC48: =AC46+AC47 -> 0
B49: TC/RC and freight | C49: US$M | D49: =SUM(F49:AC49) -> -419.40727 | F49: =-F42*$C$19 -> -25.470814 | G49: =-G42*$C$19 -> -25.470814 | H49: =-H42*$C$19 -> -25.470814 | I49: =-I42*$C$19 -> -25.470814 | J49: =-J42*$C$19 -> -25.470814 | K49: =-K42*$C$19 -> -25.470814 | L49: =-L42*$C$19 -> -25.470814 | M49: =-M42*$C$19 -> -25.470814 | ... AC49: =-AC42*$C$19 -> 0
B50: Royalties | C50: US$M | D50: =SUM(F50:AC50) -> -122.01386 | F50: =-F48*$C$25 -> -8.7328504 | G50: =-G48*$C$25 -> -8.0051129 | H50: =-H48*$C$25 -> -7.2773753 | I50: =-I48*$C$25 -> -7.2773753 | J50: =-J48*$C$25 -> -7.2773753 | K50: =-K48*$C$25 -> -7.2773753 | L50: =-L48*$C$25 -> -7.2773753 | M50: =-M48*$C$25 -> -7.2773753 | ... AC50: =-AC48*$C$25 -> 0
B51: Site operating costs | C51: US$M | D51: =SUM(F51:AC51) -> -2558.846 | F51: =-F40*$C$18 -> -155.4 | G51: =-G40*$C$18 -> -155.4 | H51: =-H40*$C$18 -> -155.4 | I51: =-I40*$C$18 -> -155.4 | J51: =-J40*$C$18 -> -155.4 | K51: =-K40*$C$18 -> -155.4 | L51: =-L40*$C$18 -> -155.4 | M51: =-M40*$C$18 -> -155.4 | ... AC51: =-AC40*$C$18 -> 0
...

Sheet Tucuma
B1: Tucumã — asset NAV (ERO, Brazil (Pará))
B2: Reserve-constrained life-of-mine model. Blue = input (data/assets.csv), green = link, black = formula. US$M real unless noted.
B4: Input | C4: Value | D4: Unit | F4: Source / status
B5: Ownership | C5: 1 | D5: % | F5: Source IDs: ERO-TUCUMA-TR;ERO-MDA-2025Q4;ERO-Q2-2026 (see Sources tab)
B6: P&P reserve (at effective date) | C6: 43.052 | D6: Mt | F6: [verified] reserve_mt|cu_grade_pct: Sep 2021 P&P 43.1 Mt @ 0.83% Cu (pre-production)
B7: Depletion to 1 Jan 2027 | C7: 6.6 | D7: Mt | F7: [estimate] depleted_mt: 2024–2026 ore processed (2025 verified at 1.81 Mt)
B8: Copper grade | C8: 0.0083 | D8: % Cu | F8: [calibrated] opex_usd_t: Set so C1 lands near the US$1.95–2.15/lb 2026 guidance
B9: Gold grade | C9: 0 | D9: g/t Au | F9: [estimate] expansion_mtpa|sustaining_usd_m: 4.4 Mtpa from 2027 reflects plant throughput upgrades due Q4 2026 (ERO-Q2-2026); sustaining capex is an analyst estimate
B10: Copper recovery | C10: 0.9 | D10: %
B11: Gold recovery | C11: 0 | D11: %
B12: Copper payable | C12: 0.965 | D12: %
B13: Gold payable | C13: 0 | D13: %
B14: Throughput | C14: 4 | D14: Mtpa
B15: Throughput after expansion | C15: 4.4 | D15: Mtpa
B16: Expansion year | C16: 2027 | D16: year
B17: First production year | C17: 2027 | D17: year
B18: Site operating cost | C18: 28 | D18: US$/t milled
B19: TC/RC and freight | C19: 0.35 | D19: US$/lb Cu
B20: Sustaining capex | C20: 25 | D20: US$M/yr
B21: Growth capex (total) | C21: 0 | D21: US$M
... B30: Stream copper price received | C30: 0 | D30: % of spot
B31: Discount rate (real) | C31: =Inputs!$C$26 -> 0.08 | D31: Inputs tab
B34: US$M unless noted | C34: Unit | D34: LOM / NPV | F34: 2027 | G34: 2028 | H34: 2029 | I34: 2030 | J34: 2031 | K34: 2032 | L34: 2033 | M34: 2034 | N34: 2035 | O34: 2036 | P34: 2037 | Q34: 2038 | R34: 2039 | S34: 2040 | T34: 2041 | U34: 2042 | V34: 2043 | W34: 2044 | X34: 2045 | Y34: 2046 | Z34: 2047 | AA34: 2048 | AB34: 2049 | AC34: 2050
B35: Period | F35: =F$34-2027+1 -> 1 | G35: =G$34-2027+1 -> 2 | H35: =H$34-2027+1 -> 3 | I35: =I$34-2027+1 -> 4 | J35: =J$34-2027+1 -> 5 | K35: =K$34-2027+1 -> 6 | L35: =L$34-2027+1 -> 7 | M35: =M$34-2027+1 -> 8 | ... AC35: =AC$34-2027+1 -> 24
B36: Copper price | C36: US$/lb | F36: =Inputs!F$18 -> 6 | G36: =Inputs!G$18 -> 5.5 | H36: =Inputs!H$18 -> 5 | I36: =Inputs!I$18 -> 5 | J36: =Inputs!J$18 -> 5 | K36: =Inputs!K$18 -> 5 | L36: =Inputs!L$18 -> 5 | M36: =Inputs!M$18 -> 5 | ... AC36: =Inputs!AC$18 -> 5
B37: Gold price | C37: US$/oz | F37: =Inputs!F$19 -> 3900 | G37: =Inputs!G$19 -> 3600 | H37: =Inputs!H$19 -> 3300 | I37: =Inputs!I$19 -> 3300 | J37: =Inputs!J$19 -> 3300 | K37: =Inputs!K$19 -> 3300 | L37: =Inputs!L$19 -> 3300 | M37: =Inputs!M$19 -> 3300 | ... AC37: =Inputs!AC$19 -> 3300
B38: Mill capacity | C38: Mt | F38: =IF(F$34<$C$17,0,IF(F$34>=$C$16,$C$15,$C$14)) -> 4.4 | G38: =IF(G$34<$C$17,0,IF(G$34>=$C$16,$C$15,$C$14)) -> 4.4 | H38: =IF(H$34<$C$17,0,IF(H$34>=$C$16,$C$15,$C$14)) -> 4.4 | I38: =IF(I$34<$C$17,0,IF(I$34>=$C$16,$C$15,$C$14)) -> 4.4 | J38: =IF(J$34<$C$17,0,IF(J$34>=$C$16,$C$15,$C$14)) -> 4.4 | K38: =IF(K$34<$C$17,0,IF(K$34>=$C$16,$C$15,$C$14)) -> 4.4 | L38: =IF(L$34<$C$17,0,IF(L$34>=$C$16,$C$15,$C$14)) -> 4.4 | M38: =IF(M$34<$C$17,0,IF(M$34>=$C$16,$C$15,$C$14)) -> 4.4 | ... AC38: =IF(AC$34<$C$17,0,IF(AC$34>=$C$16,$C$15,$C$14)) -> 4.4
B39: Opening reserve | C39: Mt | F39: =$C$6-$C$7 -> 36.452 | G39: =F41 -> 32.052 | H39: =G41 -> 27.652 | I39: =H41 -> 23.252 | J39: =I41 -> 18.852 | K39: =J41 -> 14.452 | L39: =K41 -> 10.052 | M39: =L41 -> 5.652 | N39: =M41 -> 1.252 | ... AC39: =AB41 -> 0
B40: Ore processed | C40: Mt | D40: =SUM(F40:AC40) -> 36.452 | F40: =MAX(0,MIN(F38,F39)) -> 4.4 | G40: =MAX(0,MIN(G38,G39)) -> 4.4 | H40: =MAX(0,MIN(H38,H39)) -> 4.4 | I40: =MAX(0,MIN(I38,I39)) -> 4.4 | J40: =MAX(0,MIN(J38,J39)) -> 4.4 | K40: =MAX(0,MIN(K38,K39)) -> 4.4 | L40: =MAX(0,MIN(L38,L39)) -> 4.4 | M40: =MAX(0,MIN(M38,M39)) -> 4.4 | ... AC40: =MAX(0,MIN(AC38,AC39)) -> 0
B41: Closing reserve | C41: Mt | F41: =F39-F40 -> 32.052 | G41: =G39-G40 -> 27.652 | H41: =H39-H40 -> 23.252 | I41: =I39-I40 -> 18.852 | J41: =J39-J40 -> 14.452 | K41: =K39-K40 -> 10.052 | L41: =L39-L40 -> 5.652 | M41: =M39-M40 -> 1.252 | ... AC41: =AC39-AC40 -> 0
B42: Payable copper | C42: Mlb | D42: =SUM(F42:AC42) -> 579.29932 | F42: =F40*$C$8*$C$10*$C$12*2204.62 -> 69.925299 | G42: =G40*$C$8*$C$10*$C$12*2204.62 -> 69.925299 | H42: =H40*$C$8*$C$10*$C$12*2204.62 -> 69.925299 | I42: =I40*$C$8*$C$10*$C$12*2204.62 -> 69.925299 | J42: =J40*$C$8*$C$10*$C$12*2204.62 -> 69.925299 | K42: =K40*$C$8*$C$10*$C$12*2204.62 -> 69.925299 | L42: =L40*$C$8*$C$10*$C$12*2204.62 -> 69.925299 | M42: =M40*$C$8*$C$10*$C$12*2204.62 -> 69.925299 | ... AC42: =AC40*$C$8*$C$10*$C$12*2204.62 -> 0
B43: Payable gold | C43: koz | D43: =SUM(F43:AC43) -> 0 | F43: =F40*$C$9*$C$11*$C$13*1000/31.1035 -> 0 | G43: =G40*$C$9*$C$11*$C$13*1000/31.1035 -> 0 | H43: =H40*$C$9*$C$11*$C$13*1000/31.1035 -> 0 | I43: =I40*$C$9*$C$11*$C$13*1000/31.1035 -> 0 | J43: =J40*$C$9*$C$11*$C$13*1000/31.1035 -> 0 | K43: =K40*$C$9*$C$11*$C$13*1000/31.1035 -> 0 | L43: =L40*$C$9*$C$11*$C$13*1000/31.1035 -> 0 | M43: =M40*$C$9*$C$11*$C$13*1000/31.1035 -> 0 | ... AC43: =AC40*$C$9*$C$11*$C$13*1000/31.1035 -> 0
B44: Realised copper price (after stream) | C44: US$/lb | F44: =F36*(1-$C$29)+F36*$C$29*$C$30 -> 6 | G44: =G36*(1-$C$29)+G36*$C$29*$C$30 -> 5.5 | H44: =H36*(1-$C$29)+H36*$C$29*$C$30 -> 5 | I44: =I36*(1-$C$29)+I36*$C$29*$C$30 -> 5 | J44: =J36*(1-$C$29)+J36*$C$29*$C$30 -> 5 | K44: =K36*(1-$C$29)+K36*$C$29*$C$30 -> 5 | L44: =L36*(1-$C$29)+L36*$C$29*$C$30 -> 5 | M44: =M36*(1-$C$29)+M36*$C$29*$C$30 -> 5 | ... AC44: =AC36*(1-$C$29)+AC36*$C$29*$C$30 -> 5
B45: Realised gold price (after stream) | C45: US$/oz | F45: =F37*(1-$C$27)+$C$27*$C$28 -> 3900 | G45: =G37*(1-$C$27)+$C$27*$C$28 -> 3600 | H45: =H37*(1-$C$27)+$C$27*$C$28 -> 3300 | I45: =I37*(1-$C$27)+$C$27*$C$28 -> 3300 | J45: =J37*(1-$C$27)+$C$27*$C$28 -> 3300 | K45: =K37*(1-$C$27)+$C$27*$C$28 -> 3300 | L45: =L37*(1-$C$27)+$C$27*$C$28 -> 3300 | M45: =M37*(1-$C$27)+$C$27*$C$28 -> 3300 | ... AC45: =AC37*(1-$C$27)+$C$27*$C$28 -> 3300
B46: Copper revenue | C46: US$M | D46: =SUM(F46:AC46) -> 3001.3846 | F46: =F42*F44 -> 419.5518 | G46: =G42*G44 -> 384.58915 | H46: =H42*H44 -> 349.6265 | I46: =I42*I44 -> 349.6265 | J46: =J42*J44 -> 349.6265 | K46: =K42*K44 -> 349.6265 | L46: =L42*L44 -> 349.6265 | M46: =M42*M44 -> 349.6265 | ... AC46: =AC42*AC44 -> 0
B47: Gold revenue | C47: US$M | D47: =SUM(F47:AC47) -> 0 | F47: =F43*F45/1000 -> 0 | G47: =G43*G45/1000 -> 0 | H47: =H43*H45/1000 -> 0 | I47: =I43*I45/1000 -> 0 | J47: =J43*J45/1000 -> 0 | K47: =K43*K45/1000 -> 0 | L47: =L43*L45/1000 -> 0 | M47: =M43*M45/1000 -> 0 | ... AC47: =AC43*AC45/1000 -> 0
B48: Total revenue | C48: US$M | D48: =SUM(F48:AC48) -> 3001.3846 | F48: =F46+F47 -> 419.5518 | G48: =G46+G47 -> 384.58915 | H48: =H46+H47 -> 349.6265 | I48: =I46+I47 -> 349.6265 | J48: =J46+J47 -> 349.6265 | K48: =K46+K47 -> 349.6265 | L48: =L46+L47 -> 349.6265 | M48: =M46+M47 -> 349.6265 | ... AC48: =AC46+AC47 -> 0
B49: TC/RC and freight | C49: US$M | D49: =SUM(F49:AC49) -> -202.75476 | F49: =-F42*$C$19 -> -24.473855 | G49: =-G42*$C$19 -> -24.473855 | H49: =-H42*$C$19 -> -24.473855 | I49: =-I42*$C$19 -> -24.473855 | J49: =-J42*$C$19 -> -24.473855 | K49: =-K42*$C$19 -> -24.473855 | L49: =-L42*$C$19 -> -24.473855 | M49: =-M42*$C$19 -> -24.473855 | ... AC49: =-AC42*$C$19 -> 0
B50: Royalties | C50: US$M | D50: =SUM(F50:AC50) -> -60.027691 | F50: =-F48*$C$25 -> -8.3910359 | G50: =-G48*$C$25 -> -7.6917829 | H50: =-H48*$C$25 -> -6.9925299 | I50: =-I48*$C$25 -> -6.9925299 | J50: =-J48*$C$25 -> -6.9925299 | K50: =-K48*$C$25 -> -6.9925299 | L50: =-L48*$C$25 -> -6.9925299 | M50: =-M48*$C$25 -> -6.9925299 | ... AC50: =-AC48*$C$25 -> 0
B51: Site operating costs | C51: US$M | D51: =SUM(F51:AC51) -> -1020.656 | F51: =-F40*$C$18 -> -123.2 | G51: =-G40*$C$18 -> -123.2 | H51: =-H40*$C$18 -> -123.2 | I51: =-I40*$C$18 -> -123.2 | J51: =-J40*$C$18 -> -123.2 | K51: =-K40*$C$18 -> -123.2 | L51: =-L40*$C$18 -> -123.2 | M51: =-M40*$C$18 -> -123.2 | ... AC51: =-AC40*$C$18 -> 0
...

Sheet Xavantina
B1: Xavantina — asset NAV (ERO, Brazil (Mato Grosso))
B2: Reserve-constrained life-of-mine model. Blue = input (data/assets.csv), green = link, black = formula. US$M real unless noted.
B4: Input | C4: Value | D4: Unit | F4: Source / status
B5: Ownership | C5: 0.976 | D5: % | F5: Source IDs: ERO-XAV-2025;ERO-MDA-2025Q4;ERO-Q2-2026 (see Sources tab)
B6: P&P reserve (at effective date) | C6: 1.1 | D6: Mt | F6: [estimate] reserve_mt|au_gpt: Back-solved from 2025 production (172 kt processed; 37.3 koz) and 40–50 koz/yr guidance; replace with the 2025 reserve update table
B7: Depletion to 1 Jan 2027 | C7: 0.18 | D7: Mt | F7: [calibrated] opex_usd_t|sustaining_usd_m: Set so AISC lands in the revised US$2,200–2,700/oz guidance range
B8: Copper grade | C8: 0 | D8: % Cu
B9: Gold grade | C9: 6.8 | D9: g/t Au
B10: Copper recovery | C10: 0 | D10: %
B11: Gold recovery | C11: 0.92 | D11: %
B12: Copper payable | C12: 0 | D12: %
B13: Gold payable | C13: 0.999 | D13: %
B14: Throughput | C14: 0.2 | D14: Mtpa
B15: Throughput after expansion | C15: 0.2 | D15: Mtpa
B16: Expansion year | C16: 2027 | D16: year
B17: First production year | C17: 2027 | D17: year
B18: Site operating cost | C18: 270 | D18: US$/t milled
B19: TC/RC and freight | C19: 0 | D19: US$/lb Cu
... B30: Stream copper price received | C30: 0 | D30: % of spot
B31: Discount rate (real) | C31: =Inputs!$C$27 -> 0.05 | D31: Inputs tab
B34: US$M unless noted | C34: Unit | D34: LOM / NPV | F34: 2027 | G34: 2028 | H34: 2029 | I34: 2030 | J34: 2031 | K34: 2032 | L34: 2033 | M34: 2034 | N34: 2035 | O34: 2036 | P34: 2037 | Q34: 2038 | R34: 2039 | S34: 2040 | T34: 2041 | U34: 2042 | V34: 2043 | W34: 2044 | X34: 2045 | Y34: 2046 | Z34: 2047 | AA34: 2048 | AB34: 2049 | AC34: 2050
B35: Period | F35: =F$34-2027+1 -> 1 | G35: =G$34-2027+1 -> 2 | H35: =H$34-2027+1 -> 3 | I35: =I$34-2027+1 -> 4 | J35: =J$34-2027+1 -> 5 | K35: =K$34-2027+1 -> 6 | L35: =L$34-2027+1 -> 7 | M35: =M$34-2027+1 -> 8 | ... AC35: =AC$34-2027+1 -> 24
B36: Copper price | C36: US$/lb | F36: =Inputs!F$18 -> 6 | G36: =Inputs!G$18 -> 5.5 | H36: =Inputs!H$18 -> 5 | I36: =Inputs!I$18 -> 5 | J36: =Inputs!J$18 -> 5 | K36: =Inputs!K$18 -> 5 | L36: =Inputs!L$18 -> 5 | M36: =Inputs!M$18 -> 5 | ... AC36: =Inputs!AC$18 -> 5
B37: Gold price | C37: US$/oz | F37: =Inputs!F$19 -> 3900 | G37: =Inputs!G$19 -> 3600 | H37: =Inputs!H$19 -> 3300 | I37: =Inputs!I$19 -> 3300 | J37: =Inputs!J$19 -> 3300 | K37: =Inputs!K$19 -> 3300 | L37: =Inputs!L$19 -> 3300 | M37: =Inputs!M$19 -> 3300 | ... AC37: =Inputs!AC$19 -> 3300
B38: Mill capacity | C38: Mt | F38: =IF(F$34<$C$17,0,IF(F$34>=$C$16,$C$15,$C$14)) -> 0.2 | G38: =IF(G$34<$C$17,0,IF(G$34>=$C$16,$C$15,$C$14)) -> 0.2 | H38: =IF(H$34<$C$17,0,IF(H$34>=$C$16,$C$15,$C$14)) -> 0.2 | I38: =IF(I$34<$C$17,0,IF(I$34>=$C$16,$C$15,$C$14)) -> 0.2 | J38: =IF(J$34<$C$17,0,IF(J$34>=$C$16,$C$15,$C$14)) -> 0.2 | K38: =IF(K$34<$C$17,0,IF(K$34>=$C$16,$C$15,$C$14)) -> 0.2 | L38: =IF(L$34<$C$17,0,IF(L$34>=$C$16,$C$15,$C$14)) -> 0.2 | M38: =IF(M$34<$C$17,0,IF(M$34>=$C$16,$C$15,$C$14)) -> 0.2 | ... AC38: =IF(AC$34<$C$17,0,IF(AC$34>=$C$16,$C$15,$C$14)) -> 0.2
B39: Opening reserve | C39: Mt | F39: =$C$6-$C$7 -> 0.92 | G39: =F41 -> 0.72 | H39: =G41 -> 0.52 | I39: =H41 -> 0.32 | J39: =I41 -> 0.12 | K39: =J41 -> 0 | L39: =K41 -> 0 | M39: =L41 -> 0 | N39: =M41 -> 0 | ... AC39: =AB41 -> 0
B40: Ore processed | C40: Mt | D40: =SUM(F40:AC40) -> 0.92 | F40: =MAX(0,MIN(F38,F39)) -> 0.2 | G40: =MAX(0,MIN(G38,G39)) -> 0.2 | H40: =MAX(0,MIN(H38,H39)) -> 0.2 | I40: =MAX(0,MIN(I38,I39)) -> 0.2 | J40: =MAX(0,MIN(J38,J39)) -> 0.12 | K40: =MAX(0,MIN(K38,K39)) -> 0 | L40: =MAX(0,MIN(L38,L39)) -> 0 | M40: =MAX(0,MIN(M38,M39)) -> 0 | ... AC40: =MAX(0,MIN(AC38,AC39)) -> 0
B41: Closing reserve | C41: Mt | F41: =F39-F40 -> 0.72 | G41: =G39-G40 -> 0.52 | H41: =H39-H40 -> 0.32 | I41: =I39-I40 -> 0.12 | J41: =J39-J40 -> 0 | K41: =K39-K40 -> 0 | L41: =L39-L40 -> 0 | M41: =M39-M40 -> 0 | ... AC41: =AC39-AC40 -> 0
B42: Payable copper | C42: Mlb | D42: =SUM(F42:AC42) -> 0 | F42: =F40*$C$8*$C$10*$C$12*2204.62 -> 0 | G42: =G40*$C$8*$C$10*$C$12*2204.62 -> 0 | H42: =H40*$C$8*$C$10*$C$12*2204.62 -> 0 | I42: =I40*$C$8*$C$10*$C$12*2204.62 -> 0 | J42: =J40*$C$8*$C$10*$C$12*2204.62 -> 0 | K42: =K40*$C$8*$C$10*$C$12*2204.62 -> 0 | L42: =L40*$C$8*$C$10*$C$12*2204.62 -> 0 | M42: =M40*$C$8*$C$10*$C$12*2204.62 -> 0 | ... AC42: =AC40*$C$8*$C$10*$C$12*2204.62 -> 0
B43: Payable gold | C43: koz | D43: =SUM(F43:AC43) -> 184.85908 | F43: =F40*$C$9*$C$11*$C$13*1000/31.1035 -> 40.186757 | G43: =G40*$C$9*$C$11*$C$13*1000/31.1035 -> 40.186757 | H43: =H40*$C$9*$C$11*$C$13*1000/31.1035 -> 40.186757 | I43: =I40*$C$9*$C$11*$C$13*1000/31.1035 -> 40.186757 | J43: =J40*$C$9*$C$11*$C$13*1000/31.1035 -> 24.112054 | K43: =K40*$C$9*$C$11*$C$13*1000/31.1035 -> 0 | L43: =L40*$C$9*$C$11*$C$13*1000/31.1035 -> 0 | M43: =M40*$C$9*$C$11*$C$13*1000/31.1035 -> 0 | ... AC43: =AC40*$C$9*$C$11*$C$13*1000/31.1035 -> 0
B44: Realised copper price (after stream) | C44: US$/lb | F44: =F36*(1-$C$29)+F36*$C$29*$C$30 -> 6 | G44: =G36*(1-$C$29)+G36*$C$29*$C$30 -> 5.5 | H44: =H36*(1-$C$29)+H36*$C$29*$C$30 -> 5 | I44: =I36*(1-$C$29)+I36*$C$29*$C$30 -> 5 | J44: =J36*(1-$C$29)+J36*$C$29*$C$30 -> 5 | K44: =K36*(1-$C$29)+K36*$C$29*$C$30 -> 5 | L44: =L36*(1-$C$29)+L36*$C$29*$C$30 -> 5 | M44: =M36*(1-$C$29)+M36*$C$29*$C$30 -> 5 | ... AC44: =AC36*(1-$C$29)+AC36*$C$29*$C$30 -> 5
B45: Realised gold price (after stream) | C45: US$/oz | F45: =F37*(1-$C$27)+$C$27*$C$28 -> 3900 | G45: =G37*(1-$C$27)+$C$27*$C$28 -> 3600 | H45: =H37*(1-$C$27)+$C$27*$C$28 -> 3300 | I45: =I37*(1-$C$27)+$C$27*$C$28 -> 3300 | J45: =J37*(1-$C$27)+$C$27*$C$28 -> 3300 | K45: =K37*(1-$C$27)+$C$27*$C$28 -> 3300 | L45: =L37*(1-$C$27)+$C$27*$C$28 -> 3300 | M45: =M37*(1-$C$27)+$C$27*$C$28 -> 3300 | ... AC45: =AC37*(1-$C$27)+$C$27*$C$28 -> 3300
B46: Copper revenue | C46: US$M | D46: =SUM(F46:AC46) -> 0 | F46: =F42*F44 -> 0 | G46: =G42*G44 -> 0 | H46: =H42*H44 -> 0 | I46: =I42*I44 -> 0 | J46: =J42*J44 -> 0 | K46: =K42*K44 -> 0 | L46: =L42*L44 -> 0 | M46: =M42*M44 -> 0 | ... AC46: =AC42*AC44 -> 0
B47: Gold revenue | C47: US$M | D47: =SUM(F47:AC47) -> 646.20305 | F47: =F43*F45/1000 -> 156.72835 | G47: =G43*G45/1000 -> 144.67233 | H47: =H43*H45/1000 -> 132.6163 | I47: =I43*I45/1000 -> 132.6163 | J47: =J43*J45/1000 -> 79.569779 | K47: =K43*K45/1000 -> 0 | L47: =L43*L45/1000 -> 0 | M47: =M43*M45/1000 -> 0 | ... AC47: =AC43*AC45/1000 -> 0
B48: Total revenue | C48: US$M | D48: =SUM(F48:AC48) -> 646.20305 | F48: =F46+F47 -> 156.72835 | G48: =G46+G47 -> 144.67233 | H48: =H46+H47 -> 132.6163 | I48: =I46+I47 -> 132.6163 | J48: =J46+J47 -> 79.569779 | K48: =K46+K47 -> 0 | L48: =L46+L47 -> 0 | M48: =M46+M47 -> 0 | ... AC48: =AC46+AC47 -> 0
B49: TC/RC and freight | C49: US$M | D49: =SUM(F49:AC49) -> 0 | F49: =-F42*$C$19 -> 0 | G49: =-G42*$C$19 -> 0 | H49: =-H42*$C$19 -> 0 | I49: =-I42*$C$19 -> 0 | J49: =-J42*$C$19 -> 0 | K49: =-K42*$C$19 -> 0 | L49: =-L42*$C$19 -> 0 | M49: =-M42*$C$19 -> 0 | ... AC49: =-AC42*$C$19 -> 0
B50: Royalties | C50: US$M | D50: =SUM(F50:AC50) -> -9.6930458 | F50: =-F48*$C$25 -> -2.3509253 | G50: =-G48*$C$25 -> -2.1700849 | H50: =-H48*$C$25 -> -1.9892445 | I50: =-I48*$C$25 -> -1.9892445 | J50: =-J48*$C$25 -> -1.1935467 | K50: =-K48*$C$25 -> 0 | L50: =-L48*$C$25 -> 0 | M50: =-M48*$C$25 -> 0 | ... AC50: =-AC48*$C$25 -> 0
B51: Site operating costs | C51: US$M | D51: =SUM(F51:AC51) -> -248.4 | F51: =-F40*$C$18 -> -54 | G51: =-G40*$C$18 -> -54 | H51: =-H40*$C$18 -> -54 | I51: =-I40*$C$18 -> -54 | J51: =-J40*$C$18 -> -32.4 | K51: =-K40*$C$18 -> 0 | L51: =-L40*$C$18 -> 0 | M51: =-M40*$C$18 -> 0 | ... AC51: =-AC40*$C$18 -> 0
B52: Mine EBITDA | C52: US$M | D52: =SUM(F52:AC52) -> 388.11001 | F52: =SUM(F48:F51) -> 100.37743 | G52: =SUM(G48:G51) -> 88.502241 | H52: =SUM(H48:H51) -> 76.627054 | I52: =SUM(I48:I51) -> 76.627054 | J52: =SUM(J48:J51) -> 45.976232 | K52: =SUM(K48:K51) -> 0 | L52: =SUM(L48:L51) -> 0 | M52: =SUM(M48:M51) -> 0 | ... AC52: =SUM(AC48:AC51) -> 0
B53: Sustaining capex | C53: US$M | D53: =SUM(F53:AC53) -> -200 | F53: =-IF(F40>0,$C$20,0) -> -40 | G53: =-IF(G40>0,$C$20,0) -> -40 | H53: =-IF(H40>0,$C$20,0) -> -40 | I53: =-IF(I40>0,$C$20,0) -> -40 | J53: =-IF(J40>0,$C$20,0) -> -40 | K53: =-IF(K40>0,$C$20,0) -> 0 | L53: =-IF(L40>0,$C$20,0) -> 0 | M53: =-IF(M40>0,$C$20,0) -> 0 | ... AC53: =-IF(AC40>0,$C$20,0) -> 0
...

Sheet Corporate_NAV
B1: Corporate NAV and financial summary
B2: Sum of attributable asset NAVs plus corporate items. P/NAV uses the spot share price and spot CAD/USD.
B4: US$M unless noted | C4: Centerra (CG) | D4: Ero (ERO) | G4: Note
B5: Mount Milligan NAV | C5: =MtMilligan!$C$63 -> 927.73859 | D5: 0
B6: Öksüt NAV | C6: =Oksut!$C$63 -> 297.7909 | D6: 0
B7: Goldfield NAV | C7: =Goldfield!$C$63 -> 239.48767 | D7: 0
B8: Caraíba NAV | C8: 0 | D8: =Caraiba!$C$63 -> 970.67724
B9: Tucumã NAV | C9: 0 | D9: =Tucuma!$C$63 -> 936.15474
B10: Xavantina NAV | C10: 0 | D10: =Xavantina!$C$63 -> 99.664503
B11: Total attributable asset NAV | C11: =SUM(C5:C10) -> 1465.0172 | D11: =SUM(D5:D10) -> 2006.4965
B12: Corporate G&A (capitalised) | C12: =-50*(1-(1+Inputs!$C$31)^-Inputs!$C$30)/Inputs!$C$31 -> -386.08675 | D12: =-40*(1-(1+Inputs!$C$31)^-Inputs!$C$30)/Inputs!$C$31 -> -308.8694 | G12: G&A (US$M/yr, data/corporate.csv) x annuity factor
B13: Other assets and exploration | C13: 200 | D13: 100 | G13: CG: Molybdenum business (Langeloth, Thompson Creek), Kemess and exploration; ERO: Furnas earn-in and regional exploration
B14: Hedge book mark-to-market | C14: 0 | D14: 0 | G14: Neither company has a material hedge book
B15: Cash and equivalents | C15: =Market!$G$5 -> 453.10301 | D15: =Market!$G$6 -> 101.742 | G15: Market tab
B16: Debt | C16: =-Market!$H$5 -> -45.762 | D16: =-Market!$H$6 -> -573.35501 | G16: Market tab
B17: Net asset value | C17: =SUM(C11:C16) -> 1686.2714 | D17: =SUM(D11:D16) -> 1326.0141
B18: Shares outstanding (M) | C18: =Market!$E$5 -> 198.59506 | D18: =Market!$E$6 -> 104.30263 | G18: Basic shares; Market tab
B19: NAV per share (US$) | C19: =C17/C18 -> 8.4910041 | D19: =D17/D18 -> 12.713141
B20: NAV per share (C$) | C20: =C19/Inputs!$C$7 -> 11.890497 | D20: =D19/Inputs!$C$7 -> 17.803026
B21: Share price (C$) | C21: =Market!$D$5 -> 28.32 | D21: =Market!$D$6 -> 42.03
B22: P/NAV | C22: =C21/C20 -> 2.3817339 | D22: =D21/D20 -> 2.3608346
B24: Financial summary (feeds the accretion/dilution analysis)
B25: US$M unless noted | C25: CG 2027E | D25: CG 2028E | E25: ERO 2027E | F25: ERO 2028E
B26: Payable copper (Mlb, attributable) | C26: =MtMilligan!F42*MtMilligan!$C$5+Oksut!F42*Oksut!$C$5+Goldfield!F42*Goldfield!$C$5 -> 58.547652 | D26: =MtMilligan!G42*MtMilligan!$C$5+Oksut!G42*Oksut!$C$5+Goldfield!G42*Goldfield!$C$5 -> 58.547652 | E26: =Caraiba!F42*Caraiba!$C$5+Tucuma!F42*Tucuma!$C$5+Xavantina!F42*Xavantina!$C$5 -> 142.69905 | F26: =Caraiba!G42*Caraiba!$C$5+Tucuma!G42*Tucuma!$C$5+Xavantina!G42*Xavantina!$C$5 -> 142.69905
